<?xml version="1.0" ?>
  <robot name="robot_model">

    <link name="robot">
    </link>
     
    <joint name="robot_to_base" type="fixed">
		  <parent link="robot"/>
		  <child link="base"/>
		  <origin rpy="0 0 0" xyz="0.00 0 0.05"/>
		  <limit effort="100" velocity="100"/>
		  <joint_properties damping="0.0" friction="10"/>
	  </joint>

	  <link name="base">
		  <visual>
			  <geometry>
				  <cylinder radius="0.06" length="0.02"/>
			  </geometry>
			  <material name="blue">
				  <color rgba="0 0 .8 1"/>
			  </material>
		  </visual>
		  <collision>
			  <geometry>
				  <cylinder radius="0.06" length="0.02"/>
			  </geometry>
		  </collision>
		  <inertial>
			  <origin rpy="0 0 0" xyz="0.000000 0.000000 0.000000"/>
			  <mass value="1"/>
			  <inertia ixx="0.0104" ixy="0" ixz="0" iyy="0.05638" iyz="0" izz="0.0500"/>
		  </inertial>
	  </link>
	  
	  <link name="caster">
	    <collision name='caster_collision'>
        <geometry>
          <sphere radius="0.02"/>
        </geometry>

        <surface>
          <friction>
            <ode>
              <mu>0</mu>
              <mu2>0</mu2>
              <slip1>1.0</slip1>
              <slip2>1.0</slip2>
            </ode>
          </friction>
        </surface>
      </collision>
      
      <visual name='caster_visual'>
        <geometry>
          <sphere radius="0.02"/>
        </geometry>
      </visual>
      
      <inertial>
			  <origin rpy="0 0 0" xyz="0.000000 0.000000 0.000000"/>
			  <mass value="3"/>
			  <inertia ixx="0.0104" ixy="0" ixz="0" iyy="0.05638" iyz="0" izz="0.0500"/>
		  </inertial>
	  </link>
	  
	  <joint name="base_to_caster" type="fixed">
		  <parent link="base"/>
		  <child link="caster"/>
		  <origin rpy="0 0 0 " xyz="-.06 0. -0.0375"/>
		  <limit effort="100" velocity="100"/>
		  <joint_properties damping="0.0" friction="10"/>
	  </joint>

	  <link name="front_right_wheel">
		  <visual>
			  <geometry>
				  <cylinder length="0.01" radius="0.0375"/>
			  </geometry>
			  <origin rpy="0 1.57075 0" xyz="0 0 0"/>
			  <material name="black">
				  <color rgba="0 0 0 1"/>
			  </material>
		  </visual>	
		  <inertial>
			  <origin rpy="0 0 0" xyz="0.000000 0.000000 0.000000"/>
			  <mass value="1.5"/>
			  <inertia ixx="0.0000329" ixy="0" ixz="0" iyy="0.0000329" iyz="0" izz="0.0000625"/>
		  </inertial>
		  <surface>
          <friction>
            <ode>
              <mu>0.6</mu>
              <mu2>0.6</mu2>
            </ode>
          </friction>
        </surface>
		  <collision>
			  <geometry>
				  <cylinder length="0.02" radius="0.0375"/>
			  </geometry>
			  <origin rpy="0 1.57075 0" xyz="0 0 0"/>
		  </collision>
	  </link>


	  <joint name="front_base_to_right_wheel" type="continuous">
		  <parent link="base"/>
		  <child link="front_right_wheel"/>
		  <origin rpy="0 0 1.57" xyz="0 0.08 -0.02"/>
		  <limit effort="100" velocity="100"/>
		  <joint_properties damping="0.0" friction="10"/>
		 
	  </joint>

	  <link name="front_left_wheel">
		  <visual>
			  <geometry>
				  <cylinder length="0.01" radius="0.0375"/>
			  </geometry>
			  <origin rpy="0 1.57075 0" xyz="0 0 0"/>
			  <material name="black">
				  <color rgba="0 0 0 1"/>
			  </material>
		  </visual>	
		  <inertial>
			  <origin rpy="0 0 0" xyz="0.000000 0.000000 0.000000"/>
			  <mass value="1.5"/>
			  <inertia ixx="0.0000329" ixy="0" ixz="0" iyy="0.0000329" iyz="0" izz="0.0000625"/>
		  </inertial>
		  <surface>
          <friction>
            <ode>
              <mu>0.6</mu>
              <mu2>0.6</mu2>
            </ode>
          </friction>
        </surface>
		  <collision>
			  <geometry>
				  <cylinder length="0.02" radius="0.0375"/>
			  </geometry>
			  <origin rpy="0 1.57075 0" xyz="0 0 0"/>
		  </collision>
	  </link>


	  <joint name="front_base_to_left_wheel" type="continuous">
		  <parent link="base"/>
		  <child link="front_left_wheel"/>
		  <origin rpy="0 0 1.57" xyz="0 -0.08 -0.02"/>
		  <limit effort="100" velocity="100"/>
		  <joint_properties damping="0.0" friction="10"/>
	  </joint>

    <link name="top">
      <visual>
			  <geometry>
				  <cylinder radius="0.06" length="0.02"/>
			  </geometry>
			  <material name="blue">
				  <color rgba="0 0 .8 1"/>
			  </material>
		  </visual>
		  <collision>
			  <geometry>
				  <cylinder radius="0.06" length="0.02"/>
			  </geometry>
		  </collision>
		  <inertial>
			  <origin rpy="0 0 0" xyz="0.000000 0.000000 0.000000"/>
			  <mass value="1"/>
			  <inertia ixx="0.0104" ixy="0" ixz="0" iyy="0.05638" iyz="0" izz="0.0500"/>
		  </inertial>
	  </link>

    <joint name="base_to_top" type="fixed">
		  <parent link="base"/>
		  <child link="top"/>
		  <origin rpy="0 0 0" xyz="0.00 0 0.06"/>
		  <limit effort="100" velocity="100"/>
		  <joint_properties damping="0.0" friction="10"/>
	  </joint>

    <link name="usb_cam">
      <visual>
			  <geometry>
				  <sphere radius="0.025"/>
			  </geometry>
			  <material name="green">
				  <color rgba="0 .8 0 1"/>
			  </material>
		  </visual>
		  <collision>
			  <geometry>
				  <sphere radius="0.025"/>
			  </geometry>
		  </collision>
		  <inertial>
			  <origin rpy="0 0 0" xyz="0.000000 0.000000 0.000000"/>
			  <mass value="0.1"/>
			  <inertia ixx="0.0104" ixy="0" ixz="0" iyy="0.05638" iyz="0" izz="0.0500"/>
		  </inertial>
	  </link>
    <joint name="top_to_usb_cam" type="fixed">
		  <parent link="top"/>
		  <child link="usb_cam"/>
		  <origin rpy="0 0 0" xyz="0.06 0 0.05"/>
		  <limit effort="100" velocity="100"/>
		  <joint_properties damping="0.0" friction="10"/>
	  </joint>


    
    <!-- camera -->
    <gazebo reference="usb_cam">
      <sensor type="camera" name="camera1">
        <update_rate>30.0</update_rate>
        <camera name="head">
          <horizontal_fov>1.3962634</horizontal_fov>
          <image>
            <width>480</width>
            <height>480</height>
            <format>R8G8B8</format>
          </image>
          <clip>
            <near>0.02</near>
            <far>300</far>
          </clip>
          <noise>
            <type>gaussian</type>
            <!-- Noise is sampled independently per pixel on each frame.
                 That pixel's noise value is added to each of its color
                 channels, which at that point lie in the range [0,1]. -->
            <mean>0.0</mean>
            <stddev>0.007</stddev>
          </noise>
        </camera>
        <plugin name="camera_controller" filename="libgazebo_ros_camera.so">
          <alwaysOn>true</alwaysOn>
          <updateRate>0.0</updateRate>
          <cameraName>/usb_cam</cameraName>
          <imageTopicName>image_raw</imageTopicName>
          <cameraInfoTopicName>camera_info</cameraInfoTopicName>
          <frameName>camera_link</frameName>
          <hackBaseline>0.07</hackBaseline>
          <distortionK1>0.0</distortionK1>
          <distortionK2>0.0</distortionK2>
          <distortionK3>0.0</distortionK3>
          <distortionT1>0.0</distortionT1>
          <distortionT2>0.0</distortionT2>
        </plugin>
      </sensor>
      
    </gazebo>
    
    <gazebo>
      <plugin name="differential_drive_controller" filename="libgazebo_ros_diff_drive.so">
        <alwaysOn>true</alwaysOn>
        <updateRate>30</updateRate>
        <legacyMode>false</legacyMode>
        <leftJoint>front_base_to_left_wheel</leftJoint>
        <rightJoint>front_base_to_right_wheel</rightJoint>
        <wheelSeparation>0.12</wheelSeparation>
        <wheelDiameter>0.07</wheelDiameter>
        <torque>50</torque>
        <commandTopic>cmd_vel</commandTopic>
        <odometryTopic>odom</odometryTopic>
        <odometryFrame>odom</odometryFrame>
        <robotBaseFrame>base</robotBaseFrame>
      </plugin>
    </gazebo>
    

  </robot>
